Workbook

Sheet Info
A1: Meal Planning Diary
A2: Patient | B2: Sam
A3: Practitioner | B3: Dr Lelde
A4: Period | B4: 23 Feb 2026 - 20 Mar 2026
A5: First Call | B5: 20 Mar 2026
A7: Data Sources
A8: Recipes | B8: Notion - Weekly Meals v2 / Recipe Database
A9: Glucose | B9: Manual entry (Dexcom integration planned)
A10: Activity/Sleep | B10: Oura Ring (integration planned)
A12: Nutritional Estimates
A13: Method | B13: Calculated from ingredient lists in Notion recipes
A14: Accuracy | B14: Estimates only - based on standard nutritional databases
A16: Glucose Thresholds
A17: Target range | B17: 4.0 - 7.8 mmol/L (per Dr Lelde)
A18: Flag threshold | B18: >7.8 mmol/L post-meal

Sheet Daily Log
A1: Date | B1: Day | C1: Meal | D1: Recipe / Food | E1: Portion | F1: Calories (kcal) | G1: Protein (g) | H1: Carbs (g) | I1: Fat (g) | J1: Fibre (g) | K1: Notes | L1: Glucose Notes
A2: 46076 | B2: Monday | C2: Breakfast
A3: 46076 | C3: Lunch
A4: 46076 | C4: Dinner | D4: Pesto pasta with white beans & halloumi | E4: 1 | F4: 685 | G4: 28 | H4: 72 | I4: 32 | J4: 8 | K4: Ottolenghi recipe from Notion DB | L4: Glucose spiked slightly over 7.8 mmol/L
A5: 46076 | C5: Snack
A6: 46077 | B6: Tuesday | C6: Breakfast | D6: Pesto pasta with white beans & halloumi | E6: 1 | F6: 685 | G6: 28 | H6: 72 | I6: 32 | J6: 8 | K6: Leftovers from last night | L6: Glucose spiked slightly over 7.8 mmol/L again
A7: 46077 | C7: Lunch | D7: Veggie chilli with silken tofu | E7: 1 | F7: 330 | G7: 19 | H7: 43 | I7: 9 | J7: 14 | K7: Veggie chilli from Notion DB + silken tofu
A8: 46077 | C8: Dinner
A9: 46077 | C9: Snack | D9: Banana with peanut butter | E9: 1 | F9: 295 | G9: 9 | H9: 33 | I9: 16 | J9: 4
A10: 46078 | B10: Wednesday | C10: Breakfast | D10: Skipped — fasted for blood tests | K10: Fasted for 11am blood draw at E. Gulbja
A11: 46078 | C11: Lunch | D11: Mac and cheese with chicken | E11: 1 | F11: 750 | G11: 40 | H11: 55 | I11: 35 | J11: 2 | K11: Not the healthiest — convenience meal after blood tests
A12: 46078 | C12: Dinner | D12: Aubergine & lentil stew with hummus, tahini & pitta | E12: 1 | F12: 700 | G12: 20 | H12: 58 | I12: 38 | J12: 12 | K12: Homemade — roasted aubergine, Puy lentils, cherry tomatoes, spiced (cumin, garam masala, paprika), hummus, tahini, coriander, capers. Served with pitta.
A13: 46078 | C13: Snack
A14: 46079 | B14: Thursday | C14: Breakfast | D14: Can't recall
A15: 46079 | C15: Lunch | D15: Can't recall
A16: 46079 | C16: Dinner | D16: Cauliflower & sweet potato curry with rice | E16: 1 | K16: From weekly meals plan
A17: 46079 | C17: Snack
A18: 46080 | B18: Friday | C18: Breakfast | D18: Can't recall
A19: 46080 | C19: Lunch | D19: Cauliflower & sweet potato curry with rice (leftovers) | E19: 1 | K19: Leftovers from Thursday dinner
A20: 46080 | C20: Dinner | D20: Falafel + hummus + vegetarian tempura rolls + kombucha + non-alcoholic prosecco | E20: 1 | K20: Homemade spread — Middle Eastern evening. Also had kombucha + non-alcoholic prosecco (rare sugary drinks) | L20: 8.0 peak → 2.8 overnight crash. Sugary drinks likely amplified the spike from fried carbs
A21: 46080 | C21: Snack
A22: 46081 | B22: Saturday | C22: Breakfast | D22: Can't recall
A23: 46081 | C23: Lunch | D23: Air-fried falafel + kibbe with hummus | E23: 1 | K23: Leftover falafel & kibbe from Friday, air-fried at home | L23: 7.4 peak, spike-dip-spike pattern, no crash
A24: 46081 | C24: Dinner | D24: Tofu mince with gochujang and rice | E24: 1 | K24: From weekly meals plan — Korean-style tofu mince
A25: 46081 | C25: Snack
A26: 46082 | B26: Sunday | C26: Breakfast | D26: Homemade hummus + leftover falafel/kibbe | E26: 1 | K26: Big portion of hummus, with Friday leftovers
A27: 46082 | C27: Lunch | D27: Tofu mince with gochujang and rice | E27: 1 | K27: Same dish as Saturday evening, from weekly meals
A28: 46082 | C28: Dinner | D28: Mushroom pasta (small) + pelmeņi + beer | E28: 1 | K28: Small pasta portion + Latvian dumplings & beer at sauna
A29: 46082 | C29: Snack
A30: 46083 | B30: Monday | C30: Breakfast | D30: Poke bowl | E30: 1 | K30: From weekly meals plan
A31: 46083 | C31: Lunch | D31: Mushroom pasta | E31: 1 | K31: Boiled pasta + mushroom garlic sauce (no recipe)
A32: 46083 | C32: Dinner | D32: Homemade pizza + carrots + slice of cheesecake | E32: 1 | K32: Birthday party at friend's house
A33: 46083 | C33: Snack
A34: 46084 | B34: Tuesday | C34: Breakfast | D34: Mushroom pasta (smaller portion) | E34: 1 | K34: Smaller serving than yesterday. Cycled to appointment after eating | L34: Pasta for breakfast. 8.4 spike at 15:41 likely from afternoon cheesecake snack (see snack row). Day avg 5.3
A35: 46084 | C35: Lunch | D35: Poke bowl | E35: 1 | L35: Pokebowl — stable glucose as expected
A36: 46084 | C36: Dinner | D36: Poke bowl | E36: 1 | K36: Second pokebowl of the day | L36: 7.6 spike at 23:16 → 3.7 crash at 23:41. Late football (finished ~11pm) — always wrecks sleep and upsets digestion. Sleep score 74 (worst of week). The glucose crash may be exercise-induced rather than food-related
A37: 46084 | C37: Snack | D37: Peach cheesecake (1 slice) | E37: 1 | K37: Leftover from Monday birthday party. Afternoon snack ~3pm | L37: Likely cause of 8.4 mmol/L spike at 15:41 — highest of the day
A38: 46085 | B38: Wednesday | C38: Breakfast | D38: Nachos | E38: 1 | K38: Not ideal breakfast choice | L38: Morning lows 3.4-3.8 from 09:41-14:01 — reactive pattern from high-carb breakfast. Day avg 4.9. Woke from bad Tuesday night sleep (score 74)
A39: 46085 | C39: Lunch | D39: Noodles and chicken | E39: 1
A40: 46085 | C40: Dinner | D40: Black bean soup | E40: 1 | L40: 8.6 mmol/L spike at 23:16 — highest of the day. But Wednesday night sleep was good (87) — spike may have recovered cleanly without a reactive crash
...

Sheet Daily Summary
A1: Date | B1: Day | C1: Total Calories | D1: Total Protein (g) | E1: Total Carbs (g) | F1: Total Fat (g) | G1: Total Fibre (g) | H1: Meals Logged | I1: Glucose Flags
A2: 46076 | B2: Monday | C2: =SUM('Daily Log'!F2:F5) | D2: =SUM('Daily Log'!G2:G5) | E2: =SUM('Daily Log'!H2:H5) | F2: =SUM('Daily Log'!I2:I5) | G2: =SUM('Daily Log'!J2:J5) | H2: =COUNTA('Daily Log'!D2:D5) | I2: =COUNTA('Daily Log'!L2:L5)
A3: 46077 | B3: Tuesday | C3: =SUM('Daily Log'!F6:F9) | D3: =SUM('Daily Log'!G6:G9) | E3: =SUM('Daily Log'!H6:H9) | F3: =SUM('Daily Log'!I6:I9) | G3: =SUM('Daily Log'!J6:J9) | H3: =COUNTA('Daily Log'!D6:D9) | I3: =COUNTA('Daily Log'!L6:L9)
A4: 46078 | B4: Wednesday | C4: =SUM('Daily Log'!F10:F13) | D4: =SUM('Daily Log'!G10:G13) | E4: =SUM('Daily Log'!H10:H13) | F4: =SUM('Daily Log'!I10:I13) | G4: =SUM('Daily Log'!J10:J13) | H4: =COUNTA('Daily Log'!D10:D13) | I4: =COUNTA('Daily Log'!L10:L13)
A5: 46079 | B5: Thursday | C5: =SUM('Daily Log'!F14:F17) | D5: =SUM('Daily Log'!G14:G17) | E5: =SUM('Daily Log'!H14:H17) | F5: =SUM('Daily Log'!I14:I17) | G5: =SUM('Daily Log'!J14:J17) | H5: =COUNTA('Daily Log'!D14:D17) | I5: =COUNTA('Daily Log'!L14:L17)
A6: 46080 | B6: Friday | C6: =SUM('Daily Log'!F18:F21) | D6: =SUM('Daily Log'!G18:G21) | E6: =SUM('Daily Log'!H18:H21) | F6: =SUM('Daily Log'!I18:I21) | G6: =SUM('Daily Log'!J18:J21) | H6: =COUNTA('Daily Log'!D18:D21) | I6: =COUNTA('Daily Log'!L18:L21)
A7: 46081 | B7: Saturday | C7: =SUM('Daily Log'!F22:F25) | D7: =SUM('Daily Log'!G22:G25) | E7: =SUM('Daily Log'!H22:H25) | F7: =SUM('Daily Log'!I22:I25) | G7: =SUM('Daily Log'!J22:J25) | H7: =COUNTA('Daily Log'!D22:D25) | I7: =COUNTA('Daily Log'!L22:L25)
A8: 46082 | B8: Sunday | C8: =SUM('Daily Log'!F26:F29) | D8: =SUM('Daily Log'!G26:G29) | E8: =SUM('Daily Log'!H26:H29) | F8: =SUM('Daily Log'!I26:I29) | G8: =SUM('Daily Log'!J26:J29) | H8: =COUNTA('Daily Log'!D26:D29) | I8: =COUNTA('Daily Log'!L26:L29)
A9: 46083 | B9: Monday | C9: =SUM('Daily Log'!F30:F33) | D9: =SUM('Daily Log'!G30:G33) | E9: =SUM('Daily Log'!H30:H33) | F9: =SUM('Daily Log'!I30:I33) | G9: =SUM('Daily Log'!J30:J33) | H9: =COUNTA('Daily Log'!D30:D33) | I9: =COUNTA('Daily Log'!L30:L33)
A10: 46084 | B10: Tuesday | C10: =SUM('Daily Log'!F34:F37) | D10: =SUM('Daily Log'!G34:G37) | E10: =SUM('Daily Log'!H34:H37) | F10: =SUM('Daily Log'!I34:I37) | G10: =SUM('Daily Log'!J34:J37) | H10: =COUNTA('Daily Log'!D34:D37) | I10: =COUNTA('Daily Log'!L34:L37)
A11: 46085 | B11: Wednesday | C11: =SUM('Daily Log'!F38:F41) | D11: =SUM('Daily Log'!G38:G41) | E11: =SUM('Daily Log'!H38:H41) | F11: =SUM('Daily Log'!I38:I41) | G11: =SUM('Daily Log'!J38:J41) | H11: =COUNTA('Daily Log'!D38:D41) | I11: =COUNTA('Daily Log'!L38:L41)
A12: 46086 | B12: Thursday | C12: =SUM('Daily Log'!F42:F45) | D12: =SUM('Daily Log'!G42:G45) | E12: =SUM('Daily Log'!H42:H45) | F12: =SUM('Daily Log'!I42:I45) | G12: =SUM('Daily Log'!J42:J45) | H12: =COUNTA('Daily Log'!D42:D45) | I12: =COUNTA('Daily Log'!L42:L45)
A13: 46087 | B13: Friday | C13: =SUM('Daily Log'!F46:F49) | D13: =SUM('Daily Log'!G46:G49) | E13: =SUM('Daily Log'!H46:H49) | F13: =SUM('Daily Log'!I46:I49) | G13: =SUM('Daily Log'!J46:J49) | H13: =COUNTA('Daily Log'!D46:D49) | I13: =COUNTA('Daily Log'!L46:L49)
A14: 46088 | B14: Saturday | C14: =SUM('Daily Log'!F50:F53) | D14: =SUM('Daily Log'!G50:G53) | E14: =SUM('Daily Log'!H50:H53) | F14: =SUM('Daily Log'!I50:I53) | G14: =SUM('Daily Log'!J50:J53) | H14: =COUNTA('Daily Log'!D50:D53) | I14: Avg 6.2 mmol/L, peak 9.7. Activity: 14.7k steps, 3497 kcal. Sleep 66. Snowboarding holiday start.
A15: 46089 | B15: Sunday | C15: =SUM('Daily Log'!F54:F57) | D15: =SUM('Daily Log'!G54:G57) | E15: =SUM('Daily Log'!H54:H57) | F15: =SUM('Daily Log'!I54:I57) | G15: =SUM('Daily Log'!J54:J57) | H15: =COUNTA('Daily Log'!D54:D57) | I15: Avg 5.9, peak 8.9. Activity: 17k steps, 4008 kcal. Sleep 85. Big snowboarding day.
A16: 46090 | B16: Monday | C16: =SUM('Daily Log'!F58:F61) | D16: =SUM('Daily Log'!G58:G61) | E16: =SUM('Daily Log'!H58:H61) | F16: =SUM('Daily Log'!I58:I61) | G16: =SUM('Daily Log'!J58:J61) | H16: =COUNTA('Daily Log'!D58:D61) | I16: Avg 5.5, peak 9.3. Activity: 15.7k steps, 3902 kcal. Sleep 92. Solid day.
A17: 46091 | B17: Tuesday | C17: =SUM('Daily Log'!F62:F65) | D17: =SUM('Daily Log'!G62:G65) | E17: =SUM('Daily Log'!H62:H65) | F17: =SUM('Daily Log'!I62:I65) | G17: =SUM('Daily Log'!J62:J65) | H17: =COUNTA('Daily Log'!D62:D65) | I17: Avg 5.5, peak 11.6 (!). Activity: 7.8k steps, 2992 kcal. Sleep 84. Biggest glucose spike — Tyrolean carbs + beer.
A18: 46092 | B18: Wednesday | C18: =SUM('Daily Log'!F66:F69) | D18: =SUM('Daily Log'!G66:G69) | E18: =SUM('Daily Log'!H66:H69) | F18: =SUM('Daily Log'!I66:I69) | G18: =SUM('Daily Log'!J66:J69) | H18: =COUNTA('Daily Log'!D66:D69) | I18: Avg 5.6, peak 8.3. Activity: 19.9k steps, 3598 kcal. Sleep 85. Most active day. 4 beers.
A19: 46093 | B19: Thursday | C19: =SUM('Daily Log'!F70:F73) | D19: =SUM('Daily Log'!G70:G73) | E19: =SUM('Daily Log'!H70:H73) | F19: =SUM('Daily Log'!I70:I73) | G19: =SUM('Daily Log'!J70:J73) | H19: =COUNTA('Daily Log'!D70:D73) | I19: Avg 5.9, peak 11.3 (!). Oura ring dead — activity data unreliable. Calorie burn likely similar (~3000-4000). Sleep 68. Second biggest spike — Tiroler Gröstl.
A20: 46094 | B20: Friday | C20: =SUM('Daily Log'!F74:F77) | D20: =SUM('Daily Log'!G74:G77) | E20: =SUM('Daily Log'!H74:H77) | F20: =SUM('Daily Log'!I74:I77) | G20: =SUM('Daily Log'!J74:J77) | H20: =COUNTA('Daily Log'!D74:D77) | I20: Avg 5.2, peak 9.7. Activity: 21.3k steps, 4112 kcal. Sleep 89. Highest calorie burn day. Double spike from pizza + pasta.
A21: 46095 | B21: Saturday | C21: =SUM('Daily Log'!F78:F81) | D21: =SUM('Daily Log'!G78:G81) | E21: =SUM('Daily Log'!H78:H81) | F21: =SUM('Daily Log'!I78:I81) | G21: =SUM('Daily Log'!J78:J81) | H21: =COUNTA('Daily Log'!D78:D81) | I21: Avg 4.6, LOW 2.5 (!). Activity: 12.6k steps, 3357 kcal. Sleep 87. Concerning overnight low — flag for Dr Lelde.
A22: 46096 | B22: Sunday | C22: =SUM('Daily Log'!F82:F85) | D22: =SUM('Daily Log'!G82:G85) | E22: =SUM('Daily Log'!H82:H85) | F22: =SUM('Daily Log'!I82:I85) | G22: =SUM('Daily Log'!J82:J85) | H22: =COUNTA('Daily Log'!D82:D85) | I22: Partial data. Sleep 97. Rest day post-holiday.
A23: 46097 | B23: Monday | C23: =SUM('Daily Log'!F86:F89) | D23: =SUM('Daily Log'!G86:G89) | E23: =SUM('Daily Log'!H86:H89) | F23: =SUM('Daily Log'!I86:I89) | G23: =SUM('Daily Log'!J86:J89) | H23: =COUNTA('Daily Log'!D86:D89) | I23: =COUNTA('Daily Log'!L86:L89)
A24: 46098 | B24: Tuesday | C24: =SUM('Daily Log'!F90:F93) | D24: =SUM('Daily Log'!G90:G93) | E24: =SUM('Daily Log'!H90:H93) | F24: =SUM('Daily Log'!I90:I93) | G24: =SUM('Daily Log'!J90:J93) | H24: =COUNTA('Daily Log'!D90:D93) | I24: =COUNTA('Daily Log'!L90:L93)
A25: 46099 | B25: Wednesday | C25: =SUM('Daily Log'!F94:F97) | D25: =SUM('Daily Log'!G94:G97) | E25: =SUM('Daily Log'!H94:H97) | F25: =SUM('Daily Log'!I94:I97) | G25: =SUM('Daily Log'!J94:J97) | H25: =COUNTA('Daily Log'!D94:D97) | I25: =COUNTA('Daily Log'!L94:L97)
A26: 46100 | B26: Thursday | C26: =SUM('Daily Log'!F98:F101) | D26: =SUM('Daily Log'!G98:G101) | E26: =SUM('Daily Log'!H98:H101) | F26: =SUM('Daily Log'!I98:I101) | G26: =SUM('Daily Log'!J98:J101) | H26: =COUNTA('Daily Log'!D98:D101) | I26: =COUNTA('Daily Log'!L98:L101)
A27: 46101 | B27: Friday | C27: =SUM('Daily Log'!F102:F105) | D27: =SUM('Daily Log'!G102:G105) | E27: =SUM('Daily Log'!H102:H105) | F27: =SUM('Daily Log'!I102:I105) | G27: =SUM('Daily Log'!J102:J105) | H27: =COUNTA('Daily Log'!D102:D105) | I27: =COUNTA('Daily Log'!L102:L105)
A28: AVERAGES | C28: =AVERAGE(C2:C27) | D28: =AVERAGE(D2:D27) | E28: =AVERAGE(E2:E27) | F28: =AVERAGE(F2:F27) | G28: =AVERAGE(G2:G27)

Sheet Recipe Reference
A1: Recipe Name | B1: Source | C1: Cuisine | D1: Type | E1: Protein (g/portion) | F1: Est. Calories/portion | G1: Est. Carbs/portion | H1: Est. Fat/portion | I1: Favourite | J1: Notion Link
A2: Pesto pasta with white beans & halloumi | B2: Ottolenghi / delicious.com.au | C2: Italian | D2: Pasta | E2: TBC | F2: 685 | G2: 72 | H2: 32 | I2: Yes | J2: https://www.notion.so/Pesto-pasta-with-white-beans-and-halloumi-134b05970b7482b08e7701cd826cc5f7
A3: Veggie chilli | B3: Cookie and Kate | C3: Mexican/American | D3: Stew | E3: 11 | F3: 250 | G3: 40 | H3: 5 | I3: No | J3: https://www.notion.so/Veggie-chilli-2b4b05970b7480f886bccaf38cfd72d9
A4: Veggie chilli with silken tofu | B4: Cookie and Kate + tofu | C4: Mexican/American | D4: Stew | E4: 19 | F4: 330 | G4: 43 | H4: 9 | I4: No
A5: Banana with peanut butter | B5: Snack | C5: - | D5: Snack | E5: 9 | F5: 295 | G5: 33 | H5: 16 | I5: -

Sheet Glucose Tracker
A1: Date | B1: Time | C1: Meal / Food | D1: Pre-meal (mmol/L) | E1: Post-meal (mmol/L) | F1: Peak (mmol/L) | G1: Notes for Dr Lelde
A2: 46076 | B2: Evening | C2: Pesto pasta with white beans & halloumi | F2: 7.8 | G2: Slightly over 7.8 threshold. High-carb pasta meal. Flag for Lelde.
A3: 46077 | B3: Morning | C3: Pesto pasta with white beans & halloumi (leftovers) | F3: 7.8 | G3: Repeated spike over 7.8. Same meal both times. Possible pattern with this recipe.
A4: 2026-03-07 | B4: Afternoon/Evening | C4: Chicken sandwiches + filled pasta | E4: 9.7 | F4: 9.7 | G4: Multiple spike windows (15:00-16:00, 18:00, 21:00). Holiday eating — convenience food.
A5: 2026-03-10 | B5: Late afternoon | C5: Tyrolean dumpling & Kaiserspätzle + 2 Weissbier | E5: 11.6 | F5: 11.6 | G5: Biggest spike of the week. Very carb-heavy Tyrolean lunch + beer. Sustained spike 17:26-18:41.
A6: 2026-03-12 | B6: Afternoon | C6: Tiroler Gröstl (potatoes, meat, egg) | E6: 11.3 | F6: 11.3 | G6: Second biggest spike. Potato-heavy traditional dish. Also evening spike to 9.9 from ravioli dinner.
A7: 2026-03-13 | B7: Afternoon/Evening | C7: Pizza + gochujang veg pasta | E7: 9.7 | F7: 9.7 | G7: Two separate spike events — post-pizza at 15:11 and post-dinner at 19:00-20:00. 4 beers previous night may have affected baseline.
